<?xml version="1.0"?>
<robot name="m2wr" xmlns:xacro="http://www.ros.org/wiki/xacro">

  <xacro:include filename="$(find my_robot_urdf)/urdf/mybot.gazebo" />
  <xacro:include filename="$(find my_robot_urdf)/urdf/materials.xacro" />
  <xacro:include filename="$(find my_robot_urdf)/urdf/macros.xacro" />
	
 <link name="link_chassis">
    <!-- body -->
    <collision name="collision_chassis">
      <geometry>
        <box size="0.5 0.3 0.4"/>
      </geometry>
    </collision>
    <visual>
      <origin rpy="0 0 0" xyz="0 0 0.1"/>
      <geometry>
        <box size="0.5 0.3 0.4"/>
      </geometry>
      <material name="blue"/>
    </visual>
  </link>
  
  <!-- Inertial link stores the robot's inertial information -->
  <link name="inertial_link">
    <inertial>
      <mass value="45" />
      <origin xyz="-0.00065 -0.085 0.062" />
      <inertia ixx="0.6022" ixy="-0.02364" ixz="-0.1197" iyy="1.7386" iyz="-0.001544" izz="2.0296" />
    </inertial>
  </link>

  <joint name="inertial_joint" type="fixed">
    <origin xyz="0 0 0" rpy="0 0 0" />
    <parent link="link_chassis" />
    <child link="inertial_link" />
  </joint>  
  
  <!-- Wheels and Joints -->
  <link name="link_right_wheel">
    <inertial>
      <mass value="2"/>
      <origin rpy="0 1.5707 1.5707" xyz="0 0 0"/>
      <inertia ixx="0.000526666666667" ixy="0" ixz="0" iyy="0.000526666666667" iyz="0" izz="0.001"/>
    </inertial>
    <collision name="link_right_wheel_collision">
      <origin rpy="0 1.5707 1.5707" xyz="0 0 0"/>
      <geometry>
        <cylinder length="0.04" radius="0.1"/>
      </geometry>
    </collision>
    <visual name="link_right_wheel_visual">
      <origin rpy="0 1.5707 1.5707" xyz="0 0 0"/>
      <geometry>
        <cylinder length="0.04" radius="0.1"/>
      </geometry>
	  <material name="black"/>
    </visual>
  </link>
  
  <joint name="joint_right_wheel" type="continuous">
    <origin rpy="0 0 0" xyz="-0.15 0.17 -0.1"/>
    <child link="link_right_wheel"/>
    <parent link="link_chassis"/>
    <axis rpy="0 0 0" xyz="0 1 0"/>
    <limit effort="10000" velocity="1000"/>
    <joint_properties damping="1.0" friction="1.0"/>
  </joint>
  
  <link name="link_left_wheel">
    <inertial>
      <mass value="2"/>
      <origin rpy="0 1.5707 1.5707" xyz="0 0 0"/>
      <inertia ixx="0.000526666666667" ixy="0" ixz="0" iyy="0.000526666666667" iyz="0" izz="0.001"/>
    </inertial>
    <collision name="link_left_wheel_collision">
      <origin rpy="0 1.5707 1.5707" xyz="0 0 0"/>
      <geometry>
        <cylinder length="0.04" radius="0.1"/>
      </geometry>
    </collision>
    <visual name="link_left_wheel_visual">
      <origin rpy="0 1.5707 1.5707" xyz="0 0 0"/>
      <geometry>
        <cylinder length="0.04" radius="0.1"/>
      </geometry>
	  <material name="black"/>
    </visual>
  </link>
  
  <joint name="joint_left_wheel" type="continuous">
    <origin rpy="0 0 0" xyz="-0.15 -0.17 -0.1"/>
    <child link="link_left_wheel"/>
    <parent link="link_chassis"/>
    <axis rpy="0 0 0" xyz="0 1 0"/>
    <limit effort="10000" velocity="1000"/>
    <joint_properties damping="1.0" friction="1.0"/>
  </joint>
  
    <link name="link_back_right_wheel">
    <inertial>
      <mass value="2"/>
      <origin rpy="0 1.5707 1.5707" xyz="0 0 0"/>
      <inertia ixx="0.000526666666667" ixy="0" ixz="0" iyy="0.000526666666667" iyz="0" izz="0.001"/>
    </inertial>
    <collision name="link_back_right_wheel_collision">
      <origin rpy="0 1.5707 1.5707" xyz="0 0 0"/>
      <geometry>
        <cylinder length="0.04" radius="0.1"/>
      </geometry>
    </collision>
    <visual name="link_back_right_wheel_visual">
      <origin rpy="0 1.5707 1.5707" xyz="0 0 0"/>
      <geometry>
        <cylinder length="0.04" radius="0.1"/>
      </geometry>
	  <material name="black"/>
    </visual>
  </link>
  
    <joint name="joint_back_right_wheel" type="continuous">
    <origin rpy="0 0 0" xyz="0.15 0.17 -0.1"/>
    <child link="link_back_right_wheel"/>
    <parent link="link_chassis"/>
    <axis rpy="0 0 0" xyz="0 1 0"/>
    <limit effort="10000" velocity="1000"/>
    <joint_properties damping="1.0" friction="1.0"/>
  </joint>
  
    <link name="link_back_left_wheel">
    <inertial>
      <mass value="2"/>
      <origin rpy="0 1.5707 1.5707" xyz="0 0 0"/>
      <inertia ixx="0.000526666666667" ixy="0" ixz="0" iyy="0.000526666666667" iyz="0" izz="0.001"/>
    </inertial>
    <collision name="link_back_left_wheel_collision">
      <origin rpy="0 1.5707 1.5707" xyz="0 0 0"/>
      <geometry>
        <cylinder length="0.04" radius="0.1"/>
      </geometry>
    </collision>
    <visual name="link_back_left_wheel_visual">
      <origin rpy="0 1.5707 1.5707" xyz="0 0 0"/>
      <geometry>
        <cylinder length="0.04" radius="0.1"/>
      </geometry>
	  <material name="black"/>
    </visual>
  </link>
  
  <joint name="joint_back_left_wheel" type="continuous">
    <origin rpy="0 0 0" xyz="0.15 -0.17 -0.1"/>
    <child link="link_back_left_wheel"/>
    <parent link="link_chassis"/>
    <axis rpy="0 0 0" xyz="0 1 0"/>
    <limit effort="10000" velocity="1000"/>
    <joint_properties damping="1.0" friction="1.0"/>
  </joint>
  
  <!-- Camera-->
    <link name="camera">
    <collision>
      <origin xyz="0 0 0" rpy="0 0 0"/>
      <geometry>
        <box size="0.05 0.05 0.05"/>
      </geometry>
    </collision>
    <visual>
      <origin xyz="0 0 0" rpy="0 0 0"/>
      <geometry>
        <box size="0.05 0.05 0.05"/>
      </geometry>
      <material name="green"/>
    </visual>
    <inertial>
      <mass value="0.05" />
      <origin xyz="0 0 0" rpy="0 0 0"/>
      <inertia ixx="1e-6" ixy="0" ixz="0" iyy="1e-6" iyz="0" izz="1e-6" />
    </inertial>
  </link>

  <joint name="camera_joint" type="fixed">
    <axis xyz="0 1 0" />
    <origin xyz="0.275 0 0.15" rpy="0 0 0"/>
    <parent link="link_chassis"/>
    <child link="camera"/>
  </joint>
  
  <!-- Lidar Scanner-->
  <link name="laser_link">
  <collision>
   <origin xyz="0 0 0" rpy="0 0 0"/>
   <geometry>
    <box size="0.1 0.1 0.1"/>
   </geometry>
  </collision>
  <visual>
   <origin xyz="0 0 0" rpy="0 0 0"/>
    <geometry>
     <box size="0.05 0.05 0.05"/>
    </geometry>
	<material name="white"/>
  </visual>
  <inertial>
    <mass value="1e-5" />
    <origin xyz="0 0 0" rpy="0 0 0"/>
    <inertia ixx="1e-6" ixy="0" ixz="0" iyy="1e-6" iyz="0" izz="1e-6" />
  </inertial>
</link>

<joint name="laser_joint" type="fixed">
<axis xyz="0 0 0" />
<origin xyz="0.2 0 0.325" rpy="0 0 0"/>
<parent link="link_chassis"/>
<child link="laser_link"/>
</joint>
  
<!-- IMU -->
  <link name="imu_link">
  <collision>
   <origin xyz="0 0 0" rpy="0 0 0"/>
   <geometry>
    <box size="0.025 0.025 0.025"/>
   </geometry>
  </collision>
  <visual>
   <origin xyz="0 0 0" rpy="0 0 0"/>
    <geometry>
     <box size="0.025 0.025 0.025"/>
    </geometry>
	<material name="orange"/>
  </visual>
  <inertial>
    <mass value="1e-5" />
    <origin xyz="0 0 0" rpy="0 0 0"/>
    <inertia ixx="1e-6" ixy="0" ixz="0" iyy="1e-6" iyz="0" izz="1e-6" />
  </inertial>
</link>

<joint name="imu_joint" type="fixed">
<axis xyz="0 0 0" />
<origin xyz="0.0 0 0.3125" rpy="0 0 0"/>
<parent link="link_chassis"/>
<child link="imu_link"/>
</joint>
  
</robot>
